ERROR:root:Erro: list index out of range
Traceback (most recent call last):
  File "C:\etl\app-unico\main.py", line 307, in <module>
    sessions(data)
  File "C:\etl\app-unico\main.py", line 206, in sessions
    print(data[0])
          ~~~~^^^
IndexError: list index out of range
